Workbook
Name ñ617: '[1]Anexo C'!#REF!
Name OLE_LINK1_2: #REF!

Sheet CLUB 738. RELACION SOCIOS 31 DI
A1: No. REGISTRO DEL CLUB | B1: DOMICILIO DEL CLUB | C1: NOMBRE DEL SOCIO (No. CREDENCIAL) | D1: CURP | E1: No. CONSEC. DE SOCIO | F1: DOMICILIO DEL SOCIO | G1: TELEFONO | H1: EMAIL | I1: CLASE | J1: CALIBRE | K1: MARCA | L1: MODELO | M1: MATRÍCULA | N1: FOLIO | O1: ARMAS CORTAS | P1: ARMAS LARGAS | Q1: fecha_de ingreso
A2: 738 | B2: CALLE 50 No. 531-E x 69 y 71, CENTRO, 97000 MÉRIDA, YUC. | C2: 1. RICARDO JESÚS FERNÁNDEZ Y GASQUE | D2: FEGR350218HYNRSC04 | E2: 1 | F2: CALLE 44 No. 438 x 21 y 23 FRACC. LOS PINOS, MÉRIDA, YUC. CP 97138 | G2: 9999470480 | H2: richfegas@icloud.com | I2: PISTOLA | J2: .380" | K2: CESKA ZBROJOVKA | L2: CZ SHADOW 2 | M2: EP33315 | N2: A3840705 | O2: 1 | P2: 0 | Q2: =_xlfn.XLOOKUP(H2, 'Anexo A'!$E$1:$E$77, 'Anexo A'!$I$1:$I$77, "", 0) -> 39288
A3: 738 | B3: CALLE 50 No. 531-E x 69 y 71, CENTRO, 97000 MÉRIDA, YUC. | C3: 1. RICARDO JESÚS FERNÁNDEZ Y GASQUE | D3: FEGR350218HYNRSC04 | E3: 1 | F3: CALLE 44 No. 438 x 21 y 23 FRACC. LOS PINOS, MÉRIDA, YUC. CP 97138 | G3: 9999470480 | H3: richfegas@icloud.com | I3: PISTOLA | J3: .380" | K3: CESKA ZBROJOVKA | L3: CZ SHADOW 2 | M3: FP38774 | N3: A3892685 | O3: 1 | P3: 0 | Q3: =_xlfn.XLOOKUP(H3, 'Anexo A'!$E$1:$E$77, 'Anexo A'!$I$1:$I$77, "", 0) -> 39288
A4: 738 | B4: CALLE 50 No. 531-E x 69 y 71, CENTRO, 97000 MÉRIDA, YUC. | C4: 1. RICARDO JESÚS FERNÁNDEZ Y GASQUE | D4: FEGR350218HYNRSC04 | E4: 1 | F4: CALLE 44 No. 438 x 21 y 23 FRACC. LOS PINOS, MÉRIDA, YUC. CP 97138 | G4: 9999470480 | H4: richfegas@icloud.com | I4: KIT DE CONVERSION | J4: 22 LR | K4: CESKA ZBROJOVKA | L4: CZ P07 | M4: EP33673 | N4: A3860035 | O4: 1 | P4: 0 | Q4: =_xlfn.XLOOKUP(H4, 'Anexo A'!$E$1:$E$77, 'Anexo A'!$I$1:$I$77, "", 0) -> 39288
A5: 738 | B5: CALLE 50 No. 531-E x 69 y 71, CENTRO, 97000 MÉRIDA, YUC. | C5: 1. RICARDO JESÚS FERNÁNDEZ Y GASQUE | D5: FEGR350218HYNRSC04 | E5: 1 | F5: CALLE 44 No. 438 x 21 y 23 FRACC. LOS PINOS, MÉRIDA, YUC. CP 97138 | G5: 9999470480 | H5: richfegas@icloud.com | I5: RIFLE SEMIAUTOMATICO | J5: .22" L.R. | K5: TIPPMANN-ARMS | L5: M4-22 | M5: 069654 | N5: A3860045 | O5: 0 | P5: 1 | Q5: =_xlfn.XLOOKUP(H5, 'Anexo A'!$E$1:$E$77, 'Anexo A'!$I$1:$I$77, "", 0) -> 39288
A6: 738 | B6: CALLE 50 No. 531-E x 69 y 71, CENTRO, 97000 MÉRIDA, YUC. | C6: 30. JOSE JACINTO LIZARRAGA AVILA | D6: LIZJ750609HYNZVC08 | E6: 2 | F6: CALLE 25 x 22 y 24 No. 319, COL. SAN PEDRO CHOLUL, MÉRIDA, YUC. CP 97138 | G6: 9991336764 | H6: jacintolizarraga@hotmail.com | I6: PISTOLA | J6: 0.380" | K6: WALTHER | L6: PPKS | M6: 238677 | N6: A 3061194 | O6: 1 | P6: 0 | Q6: =_xlfn.XLOOKUP(H6, 'Anexo A'!$E$1:$E$77, 'Anexo A'!$I$1:$I$77, "", 0) -> 44470
A7: 738 | B7: CALLE 50 No. 531-E x 69 y 71, CENTRO, 97000 MÉRIDA, YUC. | C7: 30. JOSE JACINTO LIZARRAGA AVILA | D7: LIZJ750609HYNZVC08 | E7: 2 | F7: CALLE 25 x 22 y 24 No. 319, COL. SAN PEDRO CHOLUL, MÉRIDA, YUC. CP 97138 | G7: 9991336764 | H7: jacintolizarraga@hotmail.com | I7: PISTOLA | J7: 0.22" | K7: SMITH & WESSON | L7: 41 | M7: 41605 | N7: A 3061195 | O7: 1 | P7: 0 | Q7: =_xlfn.XLOOKUP(H7, 'Anexo A'!$E$1:$E$77, 'Anexo A'!$I$1:$I$77, "", 0) -> 44470
A8: 738 | B8: CALLE 50 No. 531-E x 69 y 71, CENTRO, 97000 MÉRIDA, YUC. | C8: 30. JOSE JACINTO LIZARRAGA AVILA | D8: LIZJ750609HYNZVC08 | E8: 2 | F8: CALLE 25 x 22 y 24 No. 319, COL. SAN PEDRO CHOLUL, MÉRIDA, YUC. CP 97138 | G8: 9991336764 | H8: jacintolizarraga@hotmail.com | I8: PISTOLA | J8: 0-380" | K8: GLOCK | L8: 25 | M8: MXF795 | N8: B 404935 | O8: 1 | P8: 0 | Q8: =_xlfn.XLOOKUP(H8, 'Anexo A'!$E$1:$E$77, 'Anexo A'!$I$1:$I$77, "", 0) -> 44470
A9: 738 | B9: CALLE 50 No. 531-E x 69 y 71, CENTRO, 97000 MÉRIDA, YUC. | C9: 30. JOSE JACINTO LIZARRAGA AVILA | D9: LIZJ750609HYNZVC08 | E9: 2 | F9: CALLE 25 x 22 y 24 No. 319, COL. SAN PEDRO CHOLUL, MÉRIDA, YUC. CP 97138 | G9: 9991336764 | H9: jacintolizarraga@hotmail.com | I9: RIFLE | J9: 0.22" L.R. | K9: WALTHER | L9: G22 | M9: WP016316 | N9: B 405098 | O9: 0 | P9: 1 | Q9: =_xlfn.XLOOKUP(H9, 'Anexo A'!$E$1:$E$77, 'Anexo A'!$I$1:$I$77, "", 0) -> 44470
A10: 738 | B10: CALLE 50 No. 531-E x 69 y 71, CENTRO, 97000 MÉRIDA, YUC. | C10: 30. JOSE JACINTO LIZARRAGA AVILA | D10: LIZJ750609HYNZVC08 | E10: 2 | F10: CALLE 25 x 22 y 24 No. 319, COL. SAN PEDRO CHOLUL, MÉRIDA, YUC. CP 97138 | G10: 9991336764 | H10: jacintolizarraga@hotmail.com | I10: RIFLE | J10: 0.22" | K10: SPRINGFIELD | L10: OF 1922 | M10: 2683B | N10: A 3061197 | O10: 0 | P10: 1 | Q10: =_xlfn.XLOOKUP(H10, 'Anexo A'!$E$1:$E$77, 'Anexo A'!$I$1:$I$77, "", 0) -> 44470
A11: 738 | B11: CALLE 50 No. 531-E x 69 y 71, CENTRO, 97000 MÉRIDA, YUC. | C11: 31. ADOLFO XACUR RIVERA | D11: XARA661008HYNCVD08 | E11: 3 | F11: Calle 36-B No. 285 x 33 y 35 COL. BENITO JUÁREZ, MÉRIDA, YUC. CP 97119 | G11: 9992442613 | H11: fit.x66@hotmail.com | I11: PISTOLA | J11: 0.380" | K11: GLOCK | L11: 25 | M11: LME199 | N11: A 2673841 | O11: 1 | P11: 0 | Q11: =_xlfn.XLOOKUP(H11, 'Anexo A'!$E$1:$E$77, 'Anexo A'!$I$1:$I$77, "", 0) -> 39822
A12: 738 | B12: CALLE 50 No. 531-E x 69 y 71, CENTRO, 97000 MÉRIDA, YUC. | C12: 31. ADOLFO XACUR RIVERA | D12: XARA661008HYNCVD08 | E12: 3 | F12: Calle 36-B No. 285 x 33 y 35 COL. BENITO JUÁREZ, MÉRIDA, YUC. CP 97119 | G12: 9992442613 | H12: fit.x66@hotmail.com | I12: REVOLVER | J12: 38 SPL | K12: SMITH & WESSON | L12: 19-3 | M12: 7 K39813 | N12: A 2673978 | O12: 1 | P12: 0 | Q12: =_xlfn.XLOOKUP(H12, 'Anexo A'!$E$1:$E$77, 'Anexo A'!$I$1:$I$77, "", 0) -> 39822
A13: 738 | B13: CALLE 50 No. 531-E x 69 y 71, CENTRO, 97000 MÉRIDA, YUC. | C13: 31. ADOLFO XACUR RIVERA | D13: XARA661008HYNCVD08 | E13: 3 | F13: Calle 36-B No. 285 x 33 y 35 COL. BENITO JUÁREZ, MÉRIDA, YUC. CP 97119 | G13: 9992442613 | H13: fit.x66@hotmail.com | I13: RIFLE | J13: 0.22" L.R. | K13: HECKLER & KOCH | L13: HK 416 D | M13: HK006418 | N13: F 198308 | O13: 0 | P13: 1 | Q13: =_xlfn.XLOOKUP(H13, 'Anexo A'!$E$1:$E$77, 'Anexo A'!$I$1:$I$77, "", 0) -> 39822
A14: 738 | B14: CALLE 50 No. 531-E x 69 y 71, CENTRO, 97000 MÉRIDA, YUC. | C14: 31. ADOLFO XACUR RIVERA | D14: XARA661008HYNCVD08 | E14: 3 | F14: Calle 36-B No. 285 x 33 y 35 COL. BENITO JUÁREZ, MÉRIDA, YUC. CP 97119 | G14: 9992442613 | H14: fit.x66@hotmail.com | I14: PISTOLA | J14: 0.380" | K14: TAURUS | L14: PT 58 HC PLUS | M14: KDS62481 | N14: F 198309 | O14: 1 | P14: 0 | Q14: =_xlfn.XLOOKUP(H14, 'Anexo A'!$E$1:$E$77, 'Anexo A'!$I$1:$I$77, "", 0) -> 39822
A15: 738 | B15: CALLE 50 No. 531-E x 69 y 71, CENTRO, 97000 MÉRIDA, YUC. | C15: 31. ADOLFO XACUR RIVERA | D15: XARA661008HYNCVD08 | E15: 3 | F15: Calle 36-B No. 285 x 33 y 35 COL. BENITO JUÁREZ, MÉRIDA, YUC. CP 97119 | G15: 9992442613 | H15: fit.x66@hotmail.com | I15: ESCOPETA | J15: 12 | K15: MOSSBERG | L15: 500 | M15: T581059 | N15: B 307607 | O15: 0 | P15: 1 | Q15: =_xlfn.XLOOKUP(H15, 'Anexo A'!$E$1:$E$77, 'Anexo A'!$I$1:$I$77, "", 0) -> 39822
A16: 738 | B16: CALLE 50 No. 531-E x 69 y 71, CENTRO, 97000 MÉRIDA, YUC. | C16: 31. ADOLFO XACUR RIVERA | D16: XARA661008HYNCVD08 | E16: 3 | F16: Calle 36-B No. 285 x 33 y 35 COL. BENITO JUÁREZ, MÉRIDA, YUC. CP 97119 | G16: 9992442613 | H16: fit.x66@hotmail.com | I16: RIFLE | J16: 0.22" | K16: JC HIGGINS | L16: 30 | M16: 2552429 | N16: B 307650 | O16: 0 | P16: 1 | Q16: =_xlfn.XLOOKUP(H16, 'Anexo A'!$E$1:$E$77, 'Anexo A'!$I$1:$I$77, "", 0) -> 39822
A17: 738 | B17: CALLE 50 No. 531-E x 69 y 71, CENTRO, 97000 MÉRIDA, YUC. | C17: 31. ADOLFO XACUR RIVERA | D17: XARA661008HYNCVD08 | E17: 3 | F17: Calle 36-B No. 285 x 33 y 35 COL. BENITO JUÁREZ, MÉRIDA, YUC. CP 97119 | G17: 9992442613 | H17: fit.x66@hotmail.com | I17: RIFLE | J17: 30 06 | K17: WINCHESTER | L17: SAKO | M17: AV597290 | N17: B 371435 | O17: 0 | P17: 1 | Q17: =_xlfn.XLOOKUP(H17, 'Anexo A'!$E$1:$E$77, 'Anexo A'!$I$1:$I$77, "", 0) -> 39822
A18: 738 | B18: CALLE 50 No. 531-E x 69 y 71, CENTRO, 97000 MÉRIDA, YUC. | C18: 31. ADOLFO XACUR RIVERA | D18: XARA661008HYNCVD08 | E18: 3 | F18: Calle 36-B No. 285 x 33 y 35 COL. BENITO JUÁREZ, MÉRIDA, YUC. CP 97119 | G18: 9992442613 | H18: fit.x66@hotmail.com | I18: REVOLVER | J18: 0.22" | K18: COLT'S | L18: SIN | M18: 23953K | N18: A 3420104 | O18: 1 | P18: 0 | Q18: =_xlfn.XLOOKUP(H18, 'Anexo A'!$E$1:$E$77, 'Anexo A'!$I$1:$I$77, "", 0) -> 39822
A19: 738 | B19: CALLE 50 No. 531-E x 69 y 71, CENTRO, 97000 MÉRIDA, YUC. | C19: 46. REMIGIO BEETHOVEN AGUILAR CANTO | D19: AUCR770225HYNGNM08 | E19: 4 | F19: 20 No. 50 x 5 y 7, COL. MÉXICO, MÉRIDA, YUC. CP 97128 | G19: 9999238686 | H19: sysaventas@hotmail.com | I19: RIFLE | J19: 0.220" SWIFT | K19: WINCHESTER | L19: 70 | M19: 138092 | N19: A 3502535 | O19: 0 | P19: 1 | Q19: =_xlfn.XLOOKUP(H19, 'Anexo A'!$E$1:$E$77, 'Anexo A'!$I$1:$I$77, "", 0) -> 44379
A20: 738 | B20: CALLE 50 No. 531-E x 69 y 71, CENTRO, 97000 MÉRIDA, YUC. | C20: 46. REMIGIO BEETHOVEN AGUILAR CANTO | D20: AUCR770225HYNGNM08 | E20: 4 | F20: 20 No. 50 x 5 y 7, COL. MÉXICO, MÉRIDA, YUC. CP 97128 | G20: 9999238686 | H20: sysaventas@hotmail.com | I20: ESCOPETA | J20: 12 | K20: BROWNING | L20: DUCKS UNLIMITED | M20: 89 DU 002435 | N20: A 2673993 | O20: 0 | P20: 1 | Q20: =_xlfn.XLOOKUP(H20, 'Anexo A'!$E$1:$E$77, 'Anexo A'!$I$1:$I$77, "", 0) -> 44379
A21: 738 | B21: CALLE 50 No. 531-E x 69 y 71, CENTRO, 97000 MÉRIDA, YUC. | C21: 46. REMIGIO BEETHOVEN AGUILAR CANTO | D21: AUCR770225HYNGNM08 | E21: 4 | F21: 20 No. 50 x 5 y 7, COL. MÉXICO, MÉRIDA, YUC. CP 97128 | G21: 9999238686 | H21: sysaventas@hotmail.com | I21: RIFLE | J21: .257" ROBERTS | K21: STEYRS | L21: 1950 | M21: 6274 | N21: B 462699 | O21: 0 | P21: 1 | Q21: =_xlfn.XLOOKUP(H21, 'Anexo A'!$E$1:$E$77, 'Anexo A'!$I$1:$I$77, "", 0) -> 44379
A22: 738 | B22: CALLE 50 No. 531-E x 69 y 71, CENTRO, 97000 MÉRIDA, YUC. | C22: 46. REMIGIO BEETHOVEN AGUILAR CANTO | D22: AUCR770225HYNGNM08 | E22: 4 | F22: 20 No. 50 x 5 y 7, COL. MÉXICO, MÉRIDA, YUC. CP 97128 | G22: 9999238686 | H22: sysaventas@hotmail.com | I22: ESCOPETA | J22: 20 GA | K22: BROWNING | L22: B-80 | M22: 471NZ11158 | N22: B 488347 | O22: 0 | P22: 1 | Q22: =_xlfn.XLOOKUP(H22, 'Anexo A'!$E$1:$E$77, 'Anexo A'!$I$1:$I$77, "", 0) -> 44379
A23: 738 | B23: CALLE 50 No. 531-E x 69 y 71, CENTRO, 97000 MÉRIDA, YUC. | C23: 46. REMIGIO BEETHOVEN AGUILAR CANTO | D23: AUCR770225HYNGNM08 | E23: 4 | F23: 20 No. 50 x 5 y 7, COL. MÉXICO, MÉRIDA, YUC. CP 97128 | G23: 9999238686 | H23: sysaventas@hotmail.com | I23: RIFLE | J23: 0.22" HORNET | K23: KIMBER | L23: 82 | M23: H1103 | N23: B 485374 | O23: 0 | P23: 1 | Q23: =_xlfn.XLOOKUP(H23, 'Anexo A'!$E$1:$E$77, 'Anexo A'!$I$1:$I$77, "", 0) -> 44379
A24: 738 | B24: CALLE 50 No. 531-E x 69 y 71, CENTRO, 97000 MÉRIDA, YUC. | C24: 46. REMIGIO BEETHOVEN AGUILAR CANTO | D24: AUCR770225HYNGNM08 | E24: 4 | F24: 20 No. 50 x 5 y 7, COL. MÉXICO, MÉRIDA, YUC. CP 97128 | G24: 9999238686 | H24: sysaventas@hotmail.com | I24: RIFLE | J24: 0.300" WBY. MAG | K24: BANSNERs | L24: X-TREME SHEEP HUNTER | M24: S6514282 | N24: B 405163 | O24: 0 | P24: 1 | Q24: =_xlfn.XLOOKUP(H24, 'Anexo A'!$E$1:$E$77, 'Anexo A'!$I$1:$I$77, "", 0) -> 44379
A25: 738 | B25: CALLE 50 No. 531-E x 69 y 71, CENTRO, 97000 MÉRIDA, YUC. | C25: 46. REMIGIO BEETHOVEN AGUILAR CANTO | D25: AUCR770225HYNGNM08 | E25: 4 | F25: 20 No. 50 x 5 y 7, COL. MÉXICO, MÉRIDA, YUC. CP 97128 | G25: 9999238686 | H25: sysaventas@hotmail.com | I25: ESCOPETA | J25: 12 | K25: BROWNING | L25: CITORI | M25: 02886 NX1B3 | N25: A 2673992 | O25: 0 | P25: 1 | Q25: =_xlfn.XLOOKUP(H25, 'Anexo A'!$E$1:$E$77, 'Anexo A'!$I$1:$I$77, "", 0) -> 44379
A26: 738 | B26: CALLE 50 No. 531-E x 69 y 71, CENTRO, 97000 MÉRIDA, YUC. | C26: 46. REMIGIO BEETHOVEN AGUILAR CANTO | D26: AUCR770225HYNGNM08 | E26: 4 | F26: 20 No. 50 x 5 y 7, COL. MÉXICO, MÉRIDA, YUC. CP 97128 | G26: 9999238686 | H26: sysaventas@hotmail.com | I26: RIFLE | J26: 0.22" L.R. | K26: RUGER | L26: 19/22 | M26: C63-1970 | N26: A 3420314 | O26: 0 | P26: 1 | Q26: =_xlfn.XLOOKUP(H26, 'Anexo A'!$E$1:$E$77, 'Anexo A'!$I$1:$I$77, "", 0) -> 44379
A27: 738 | B27: CALLE 50 No. 531-E x 69 y 71, CENTRO, 97000 MÉRIDA, YUC. | C27: 46. REMIGIO BEETHOVEN AGUILAR CANTO | D27: AUCR770225HYNGNM08 | E27: 4 | F27: 20 No. 50 x 5 y 7, COL. MÉXICO, MÉRIDA, YUC. CP 97128 | G27: 9999238686 | H27: sysaventas@hotmail.com | I27: RIFLE | J27: 0.22" L.R. | K27: CZ | L27: 452 ZKM | M27: A357238 | N27: A 3420757 | O27: 0 | P27: 1 | Q27: =_xlfn.XLOOKUP(H27, 'Anexo A'!$E$1:$E$77, 'Anexo A'!$I$1:$I$77, "", 0) -> 44379
A28: 738 | B28: CALLE 50 No. 531-E x 69 y 71, CENTRO, 97000 MÉRIDA, YUC. | C28: 46. REMIGIO BEETHOVEN AGUILAR CANTO | D28: AUCR770225HYNGNM08 | E28: 4 | F28: 20 No. 50 x 5 y 7, COL. MÉXICO, MÉRIDA, YUC. CP 97128 | G28: 9999238686 | H28: sysaventas@hotmail.com | I28: RIFLE | J28: 0.300" REM. ULTRA. MAG./ CUENTA CON CAÑÓN ADIC. CREEDMOOR CAL. 6.5 mm MAT. R/163932 | K28: BLASER | L28: R8 | M28: R/125521 | N28: A 3421384 | O28: 0 | P28: 1 | Q28: =_xlfn.XLOOKUP(H28, 'Anexo A'!$E$1:$E$77, 'Anexo A'!$I$1:$I$77, "", 0) -> 44379
A29: 738 | B29: CALLE 50 No. 531-E x 69 y 71, CENTRO, 97000 MÉRIDA, YUC. | C29: 51. MANUEL JESÚS CHAIDEZ PALACIOS | D29: CAPM841222HSLHLN09 | E29: 5 | F29: DOMICILIO CONOCIDO ANEXO 3, CERCA DE LA COCINA, BECANCHEN, TEKAX, YUC. CP 97960 | G29: 9992771732 | H29: manuel.chaidez@valledelsur.com.mx | I29: ESCOPETA | J29: 12 GA | K29: REMINGTON | L29: 870 | M29: D 062012 M | N29: A 3061142 | O29: 0 | P29: 1 | Q29: =_xlfn.XLOOKUP(H29, 'Anexo A'!$E$1:$E$77, 'Anexo A'!$I$1:$I$77, "", 0) -> 40065
A30: 738 | B30: CALLE 50 No. 531-E x 69 y 71, CENTRO, 97000 MÉRIDA, YUC. | C30: 51. MANUEL JESÚS CHAIDEZ PALACIOS | D30: CAPM841222HSLHLN09 | E30: 5 | F30: DOMICILIO CONOCIDO ANEXO 3, CERCA DE LA COCINA, BECANCHEN, TEKAX, YUC. CP 97960 | G30: 9992771732 | H30: manuel.chaidez@valledelsur.com.mx | I30: ESCOPETA | J30: 20 GA | K30: BENELLI | L30: M2 | M30: N131954S | N30: A 3061160 | O30: 0 | P30: 1 | Q30: =_xlfn.XLOOKUP(H30, 'Anexo A'!$E$1:$E$77, 'Anexo A'!$I$1:$I$77, "", 0) -> 40065
A31: 738 | B31: CALLE 50 No. 531-E x 69 y 71, CENTRO, 97000 MÉRIDA, YUC. | C31: 51. MANUEL JESÚS CHAIDEZ PALACIOS | D31: CAPM841222HSLHLN09 | E31: 5 | F31: DOMICILIO CONOCIDO ANEXO 3, CERCA DE LA COCINA, BECANCHEN, TEKAX, YUC. CP 97960 | G31: 9992771732 | H31: manuel.chaidez@valledelsur.com.mx | I31: ESCOPETA | J31: 20 GA | K31: BENELLI | L31: M2 | M31: N131929A | N31: A 3421580 | O31: 0 | P31: 1 | Q31: =_xlfn.XLOOKUP(H31, 'Anexo A'!$E$1:$E$77, 'Anexo A'!$I$1:$I$77, "", 0) -> 40065
A32: 738 | B32: CALLE 50 No. 531-E x 69 y 71, CENTRO, 97000 MÉRIDA, YUC. | C32: 51. MANUEL JESÚS CHAIDEZ PALACIOS | D32: CAPM841222HSLHLN09 | E32: 5 | F32: DOMICILIO CONOCIDO ANEXO 3, CERCA DE LA COCINA, BECANCHEN, TEKAX, YUC. CP 97960 | G32: 9992771732 | H32: manuel.chaidez@valledelsur.com.mx | I32: ESCOPETA | J32: 12 GA | K32: STOEGER | L32: 2000 | M32: 629767 | N32: A 3061140 | O32: 0 | P32: 1 | Q32: =_xlfn.XLOOKUP(H32, 'Anexo A'!$E$1:$E$77, 'Anexo A'!$I$1:$I$77, "", 0) -> 40065
A33: 738 | B33: CALLE 50 No. 531-E x 69 y 71, CENTRO, 97000 MÉRIDA, YUC. | C33: 51. MANUEL JESÚS CHAIDEZ PALACIOS | D33: CAPM841222HSLHLN09 | E33: 5 | F33: DOMICILIO CONOCIDO ANEXO 3, CERCA DE LA COCINA, BECANCHEN, TEKAX, YUC. CP 97960 | G33: 9992771732 | H33: manuel.chaidez@valledelsur.com.mx | I33: ESCOPETA | J33: 12 GA | K33: STOEGER | L33: 2000 | M33: 627884 | N33: A 3061141 | O33: 0 | P33: 1 | Q33: =_xlfn.XLOOKUP(H33, 'Anexo A'!$E$1:$E$77, 'Anexo A'!$I$1:$I$77, "", 0) -> 40065
A34: 738 | B34: CALLE 50 No. 531-E x 69 y 71, CENTRO, 97000 MÉRIDA, YUC. | C34: 53. PAULINO EDILBERTO MONFORTE TRAVA | D34: MOTP610622HYNNRL09 | E34: 6 | F34: CALLE 33 No. 331 x 18 y 20 FRACC. PEDREGALES DE TANLUM, MÉRIDA, YUC. CP 97200 | G34: 9999810995 | H34: talleresmonforte@hotmail.com | I34: ESCOPETA | J34: 20 | K34: REMINGTON | L34: 870-LW | M34: T-903674-K | N34: B 171337 | O34: 0 | P34: 1 | Q34: =_xlfn.XLOOKUP(H34, 'Anexo A'!$E$1:$E$77, 'Anexo A'!$I$1:$I$77, "", 0) -> 40148
A35: 738 | B35: CALLE 50 No. 531-E x 69 y 71, CENTRO, 97000 MÉRIDA, YUC. | C35: 53. PAULINO EDILBERTO MONFORTE TRAVA | D35: MOTP610622HYNNRL09 | E35: 6 | F35: CALLE 33 No. 331 x 18 y 20 FRACC. PEDREGALES DE TANLUM, MÉRIDA, YUC. CP 97200 | G35: 9999810995 | H35: talleresmonforte@hotmail.com | I35: ESCOPETA | J35: 12 | K35: REMINGTON | L35: 1100 | M35: N 369521 V | N35: A 1955811 | O35: 0 | P35: 1 | Q35: =_xlfn.XLOOKUP(H35, 'Anexo A'!$E$1:$E$77, 'Anexo A'!$I$1:$I$77, "", 0) -> 40148
A36: 738 | B36: CALLE 50 No. 531-E x 69 y 71, CENTRO, 97000 MÉRIDA, YUC. | C36: 53. PAULINO EDILBERTO MONFORTE TRAVA | D36: MOTP610622HYNNRL09 | E36: 6 | F36: CALLE 33 No. 331 x 18 y 20 FRACC. PEDREGALES DE TANLUM, MÉRIDA, YUC. CP 97200 | G36: 9999810995 | H36: talleresmonforte@hotmail.com | I36: ESCOPETA | J36: 12 GA | K36: FABARM | L36: LION H368 | M36: FA036796 | N36: A 3287014 | O36: 0 | P36: 1 | Q36: =_xlfn.XLOOKUP(H36, 'Anexo A'!$E$1:$E$77, 'Anexo A'!$I$1:$I$77, "", 0) -> 40148
A37: 738 | B37: CALLE 50 No. 531-E x 69 y 71, CENTRO, 97000 MÉRIDA, YUC. | C37: 53. PAULINO EDILBERTO MONFORTE TRAVA | D37: MOTP610622HYNNRL09 | E37: 6 | F37: CALLE 33 No. 331 x 18 y 20 FRACC. PEDREGALES DE TANLUM, MÉRIDA, YUC. CP 97200 | G37: 9999810995 | H37: talleresmonforte@hotmail.com | I37: RIFLE | J37: 0.22" L.R. | K37: GLENFIELD | L37: 60 | M37: 25345906 | N37: A 3287016 | O37: 0 | P37: 1 | Q37: =_xlfn.XLOOKUP(H37, 'Anexo A'!$E$1:$E$77, 'Anexo A'!$I$1:$I$77, "", 0) -> 40148
A38: 738 | B38: CALLE 50 No. 531-E x 69 y 71, CENTRO, 97000 MÉRIDA, YUC. | C38: 53. PAULINO EDILBERTO MONFORTE TRAVA | D38: MOTP610622HYNNRL09 | E38: 6 | F38: CALLE 33 No. 331 x 18 y 20 FRACC. PEDREGALES DE TANLUM, MÉRIDA, YUC. CP 97200 | G38: 9999810995 | H38: talleresmonforte@hotmail.com | I38: ESCOPETA | J38: 12 GA | K38: BROWNING | L38: XS SPECIAL | M38: 06649ZZ | N38: B 295396 | O38: 0 | P38: 1 | Q38: =_xlfn.XLOOKUP(H38, 'Anexo A'!$E$1:$E$77, 'Anexo A'!$I$1:$I$77, "", 0) -> 40148
A39: 738 | B39: CALLE 50 No. 531-E x 69 y 71, CENTRO, 97000 MÉRIDA, YUC. | C39: 53. PAULINO EDILBERTO MONFORTE TRAVA | D39: MOTP610622HYNNRL09 | E39: 6 | F39: CALLE 33 No. 331 x 18 y 20 FRACC. PEDREGALES DE TANLUM, MÉRIDA, YUC. CP 97200 | G39: 9999810995 | H39: talleresmonforte@hotmail.com | I39: RIFLE | J39: 0.243" WIN | K39: SAVAGE | L39: AXIS | M39: K839383 | N39: F 296282 | O39: 0 | P39: 1 | Q39: =_xlfn.XLOOKUP(H39, 'Anexo A'!$E$1:$E$77, 'Anexo A'!$I$1:$I$77, "", 0) -> 40148
A40: 738 | B40: CALLE 50 No. 531-E x 69 y 71, CENTRO, 97000 MÉRIDA, YUC. | C40: 53. PAULINO EDILBERTO MONFORTE TRAVA | D40: MOTP610622HYNNRL09 | E40: 6 | F40: CALLE 33 No. 331 x 18 y 20 FRACC. PEDREGALES DE TANLUM, MÉRIDA, YUC. CP 97200 | G40: 9999810995 | H40: talleresmonforte@hotmail.com | I40: RIFLE | J40: 0.243" WIN | K40: REMINGTON | L40: 700 | M40: G7138010 | N40: A 3420203 | O40: 0 | P40: 1 | Q40: =_xlfn.XLOOKUP(H40, 'Anexo A'!$E$1:$E$77, 'Anexo A'!$I$1:$I$77, "", 0) -> 40148
...

Sheet Anexo A
A1: No. DE REGISTRO | B1: NOMBRE SOCIO | C1: CURP | D1: TELEFONO | E1: EMAIL | F1: No. DE SOCIO | G1: ARMAS CORTAS | H1: ARMAS LARGAS | I1: FECHA ALTA
A2: 738 | B2: RICARDO JESUS FERNANDEZ Y GASQUE | C2: FEGR350218HYNRSC04 | D2: 9999470480 | E2: richfegas@icloud.com | F2: 1 | G2: 3 | H2: 1 | I2: 39288
A3: 738 | B3: JOSE JACINTO LIZARRAGA AVILA | C3: LIZJ750609HYNZVC08 | D3: 9991336764 | E3: jacintolizarraga@hotmail.com | F3: 30 | G3: 3 | H3: 2 | I3: 44470
A4: 738 | B4: ADOLFO XACUR RIVERA | C4: XARA661008HYNCVD08 | D4: 9992442613 | E4: fit.x66@hotmail.com | F4: 31 | G4: 4 | H4: 4 | I4: 39822
A5: 738 | B5: REMIGIO BEETHOVEN AGUILAR CANTO | C5: AUCR770225HYNGNM08 | D5: 9999238686 | E5: sysaventas@hotmail.com | F5: 46 | G5: 0 | H5: 10 | I5: 44379
A6: 738 | B6: MANUEL JESUS CHAIDEZ PALACIOS | C6: CAPM841222HSLHLN09 | D6: 9992771732 | E6: manuel.chaidez@valledelsur.com.mx | F6: 51 | G6: 0 | H6: 5 | I6: 40065
A7: 738 | B7: PAULINO EDILBERTO MONFORTE TRAVA | C7: MOTP610622HYNNRL09 | D7: 9999810995 | E7: talleresmonforte@hotmail.com | F7: 53 | G7: 0 | H7: 7 | I7: 40148
A8: 738 | B8: RIGOMAR HINOJOSA SHIELDS | C8: HISR591125HCCNHG06 | D8: 9381200721 | E8: recosadecv@prodigy.net.mx | F8: 70 | G8: 5 | H8: 5 | I8: 40452
A9: 738 | B9: JUAN CARLOS JORDAN LOPEZ | C9: JOLJ720624HYNRPN04 | D9: 9999258499 | E9: jordan910@hotmail.com | F9: 74 | G9: 0 | H9: 4 | I9: 40631
A10: 738 | B10: JORGE ALFREDO DAWN MEDINA | C10: DAMJ690611HYNWDR03 | D10: 9999005153 | E10: jorgedawn@prodigy.net.mx | F10: 87 | G10: 1 | H10: 5 | I10: 44456
A11: 738 | B11: SERGIO SANTINELLI GRAJALES | C11: SAGS611114HDFNRR05 | D11: 5554388308 | E11: ssg@santinelli.com.mx | F11: 88 | G11: 5 | H11: 3 | I11: 40749
A12: 738 | B12: CLAUDIO MAURICIO CANAVATI FARAH | C12: CAFC660725HDFNRL03 | D12: 5554536965 | E12: cc@secure.mx | F12: 97 | G12: 1 | H12: 7 | I12: 44453
A13: 738 | B13: ALEJANDRO FRANCISCO RIVAS PINTADO | C13: RIPA800807HYNVNL07 | D13: 9997720959 | E13: al3xrivas@gmail.com | F13: 99 | G13: 2 | H13: 2 | I13: 44453
... A65: 738 | B65: JESUS ALEJANDRO PUC SOSA | C65: PUSJ000131HYNCSSA4 | D65: 9993778311 | E65: alejandro18sosa@gmail.com | F65: 223 | G65: 0 | H65: 0 | I65: 45642
A66: 738 | B66: JOSE GIL HEREDIA HAGAR | C66: HEHG860310HYNRGL05 | D66: 999 900 1366 | E66: jgheredia@hotmail.com | F66: 224 | G66: 6 | H66: 1 | I66: 45642
A67: 738 | B67: SANTIAGO ALEJANDRO QUINTAL PARDES | C67: QUPS901102HYNNRN04 | D67: 9995759542 | E67: squintal158@gmail.com | F67: 225 | G67: 1 | H67: 2 | I67: 45717
A68: 738 | B68: ARIEL BALTAZAR CÓRDOBA WILSON | C68: COWA700106TSRLR00 | D68: 9994912883 | E68: atietzbabam@gmail.com | F68: 226 | G68: 3 | H68: 4 | I68: 45747
A69: 738 | B69: KRISZTIAN GOR | C69: GOXK740906HNERXR09 | D69: 13213470270 | E69: ttok09136@gmail.com | F69: 227 | G69: 0 | H69: 0 | I69: 45730
A70: 738 | B70: FABIAN MARQUEZ ORTEGA | C70: MAOF620504HDFRRB06 | D70: 9993772793 | E70: fabian.sievers3548@gmail.com | F70: 228 | G70: 2 | H70: 1 | I70: 45777
A71: 738 | B71: DANIEL DE JESUS PADILLA ROBLES | C71: PARD850710HCCDBN05 | D71: 9991650849 | E71: padilla_079@hotmail.com | F71: 229 | G71: 4 | H71: 2 | I71: 45808
A72: 738 | B72: RICARDO ANTONIO SOBERANIS GAMBOA | C72: SOGR701015HYNBMC04 | D72: 9993437376 | E72: rsoberanis11@hotmail.com | F72: 230 | G72: 1 | H72: 2 | I72: 45808
A73: 738 | B73: RAÚL CERVANTES CEBALLOS | C73: CECR890104HYNRBL02 | D73: 9993382222 | E73: rcervantes@live.com.mx | F73: 231 | G73: 0 | H73: 0 | I73: 45835
A74: 738 | B74: RICARDO DANIEL FERNÁNDEZ PÉREZ | C74: FEPR920403HYNRRC06 | D74: 999 163 9981 | E74: richfer0304@gmail.com | F74: 232 | G74: 0 | H74: 0 | I74: 45864
A75: 738 | B75: RICARDO MANUEL FERNÁNDEZ QUIJANO | C75: FEQR591020HCCRJC07 | D75: 999 947 3043 | E75: richfer1020@gmail.com | F75: 233 | G75: 1 | H75: 0 | I75: 45864
A76: 738 | B76: YAEL ROMERO DE DIOS | C76: RODY940625HYNMSL01 | D76: 999 528 7779 | E76: licyaelromero@gmail.com | F76: 234 | G76: 0 | H76: 0 | I76: 45899
A77: 738 | B77: AIMEE GOMEZ MENDOZA | C77: GOMA940118MVZMNM00 | D77: 999 730 0081 | E77: aimeegomez615@gmail.com | F77: 235 | G77: 0 | H77: 0 | I77: 46006
